Workbook

Sheet INSTRUCTIONS
A1: JEWELRY INVENTORY SYSTEM - USER GUIDE
A3: GETTING STARTED
A4: This workbook helps you manage your jewelry business inventory with ease.
A6: SHEET OVERVIEW
A7: 1. Finished Inventory | B7: Your completed jewelry pieces ready for sale
A8: 2. Raw Materials | B8: Track chains, gemstones, findings, and other supplies
A9: 3. Spool Tracker | B9: Monitor chain/wire spools and remaining material
A10: 4. Usage Log | B10: Record when you cut material from spools
A11: 5. Bundle Builder | B11: Create custom bundles by entering SKUs
A12: 6. Search & Filter | B12: Quick stats and search tools
A14: HOW TO USE THE SPOOL TRACKER
A15: Step 1: | B15: Add a new spool to the "Spool Tracker" sheet
A16: Step 2: | B16: Enter Original Length and Current Length (both start the same)
A17: Step 3: | B17: When you cut material, log it in the "Usage Log" sheet
A18: Step 4: | B18: Update the "Current Length" in Spool Tracker
B19: The "Used" column will automatically calculate how much you've used
A21: HOW TO ADD NEW FINISHED INVENTORY
A22: Step 1: | B22: Go to "Finished Inventory" sheet
A23: Step 2: | B23: Find the next empty row
A24: Step 3: | B24: Enter SKU, Category, Name, Description
A25: Step 4: | B25: Enter Metal, Size, Price, and Cost (in BLUE cells)
B26: Profit and Margin % will calculate automatically
A28: HOW TO CREATE BUNDLES
A29: Step 1: | B29: Go to "Bundle Builder" sheet
A30: Step 2: | B30: Enter a Bundle Name
A31: Step 3: | B31: Type SKUs from your inventory in the SKU column
B32: Item details will auto-fill from your inventory
A33: Step 4: | B33: Set a discount % if desired
A34: Step 5: | B34: Toggle "Yes/No" to include/exclude items
A36: COLOR CODING
A37: BLUE text | B37: Input cells - enter your data here
A38: BLACK text | B38: Calculated formulas - do not edit
A39: GREEN text | B39: Links to other sheets in this workbook
A41: TIPS
A42: • Use Excel's AutoFilter (Data > Filter) for advanced searching
A43: • Each finished piece should have a unique SKU
A44: • Keep Cost data updated for accurate profit tracking
A45: • Tags column can hold keywords for easier searching

Sheet Finished Inventory
A1: SKU | B1: Category | C1: Name | D1: Description | E1: Metal | F1: Size | G1: Price | H1: MSRP | I1: Cost | J1: Profit | K1: Margin % | L1: Notes | M1: Images | N1: Tags | P1: VIEW IMAGES →
A2: BRAC_PP10 | B2: bracelet | C2: Bracelet - Photo Print 10 | D2: Photo Print ID: Photo Print 10 | J2: =IF(AND(G2<>"",I2<>""),G2-I2,"") | K2: =IF(AND(G2<>"",G2<>0),J2/G2,"") | L2: Photo Print: Photo Print 10 | M2: https://cdn.shopify.com/s/files/1/0936/8656/3183/files/PXL_20250819_174325341.jpg?v=1761563364 | P2: To view images: Click the URL in column M, or right-click > Open Hyperlink
A3: BRAC_PP20 | B3: bracelet | C3: Bracelet - Photo Print 20 | D3: Photo Print ID: Photo Print 20 | J3: =IF(AND(G3<>"",I3<>""),G3-I3,"") | K3: =IF(AND(G3<>"",G3<>0),J3/G3,"") | L3: Photo Print: Photo Print 20 | M3: https://cdn.shopify.com/s/files/1/0936/8656/3183/files/PXL_20250819_174912278.jpg?v=1761563366
A4: BRAC_PP39 | B4: bracelet | C4: Bracelet - Photo Print 39 | D4: Photo Print ID: Photo Print 39 | J4: =IF(AND(G4<>"",I4<>""),G4-I4,"") | K4: =IF(AND(G4<>"",G4<>0),J4/G4,"") | L4: Photo Print: Photo Print 39 | M4: https://cdn.shopify.com/s/files/1/0936/8656/3183/files/PXL_20250819_174623882.jpg?v=1761563376
A5: BRAC_PP4 | B5: bracelet | C5: Bracelet - Photo Print 4 | D5: Photo Print ID: Photo Print 4 | J5: =IF(AND(G5<>"",I5<>""),G5-I5,"") | K5: =IF(AND(G5<>"",G5<>0),J5/G5,"") | L5: Photo Print: Photo Print 4 | M5: https://cdn.shopify.com/s/files/1/0936/8656/3183/files/PXL_20250819_193636787.jpg?v=1761563362
A6: BRAC_PP40 | B6: bracelet | C6: Bracelet - Photo Print 40 | D6: Photo Print ID: Photo Print 40 | J6: =IF(AND(G6<>"",I6<>""),G6-I6,"") | K6: =IF(AND(G6<>"",G6<>0),J6/G6,"") | L6: Photo Print: Photo Print 40 | M6: https://cdn.shopify.com/s/files/1/0936/8656/3183/files/PXL_20250819_193703743.jpg?v=1761563376
A7: BRAC_PP42 | B7: bracelet | C7: Bracelet - Photo Print 42 | D7: Photo Print ID: Photo Print 42 | J7: =IF(AND(G7<>"",I7<>""),G7-I7,"") | K7: =IF(AND(G7<>"",G7<>0),J7/G7,"") | L7: Photo Print: Photo Print 42 | M7: https://cdn.shopify.com/s/files/1/0936/8656/3183/files/PXL_20250819_194028193.jpg?v=1761563376
A8: BRAC_PP43 | B8: bracelet | C8: Bracelet - Photo Print 43 | D8: Photo Print ID: Photo Print 43 | J8: =IF(AND(G8<>"",I8<>""),G8-I8,"") | K8: =IF(AND(G8<>"",G8<>0),J8/G8,"") | L8: Photo Print: Photo Print 43 | M8: https://cdn.shopify.com/s/files/1/0936/8656/3183/files/PXL_20250819_174809086.jpg?v=1761563377
A9: BRAC_PP432 | B9: bracelet | C9: Bracelet - Photo Print 432 | D9: Photo Print ID: Photo Print 432 | J9: =IF(AND(G9<>"",I9<>""),G9-I9,"") | K9: =IF(AND(G9<>"",G9<>0),J9/G9,"") | L9: Photo Print: Photo Print 432 | M9: https://cdn.shopify.com/s/files/1/0936/8656/3183/files/necklace6.jpg?v=1764260388
A10: BRAC_PP45 | B10: bracelet | C10: Bracelet - Photo Print 45 | D10: Photo Print ID: Photo Print 45 | J10: =IF(AND(G10<>"",I10<>""),G10-I10,"") | K10: =IF(AND(G10<>"",G10<>0),J10/G10,"") | L10: Photo Print: Photo Print 45 | M10: https://cdn.shopify.com/s/files/1/0936/8656/3183/files/PXL_20250819_193925175.jpg?v=1761563377
A11: BRAC_PP46 | B11: bracelet | C11: Bracelet - Photo Print 46 | D11: Photo Print ID: Photo Print 46 | J11: =IF(AND(G11<>"",I11<>""),G11-I11,"") | K11: =IF(AND(G11<>"",G11<>0),J11/G11,"") | L11: Photo Print: Photo Print 46 | M11: https://cdn.shopify.com/s/files/1/0936/8656/3183/files/PXL_20250819_174217542.jpg?v=1761563377
A12: BRAC_PP47 | B12: bracelet | C12: Bracelet - Photo Print 47 | D12: Photo Print ID: Photo Print 47 | J12: =IF(AND(G12<>"",I12<>""),G12-I12,"") | K12: =IF(AND(G12<>"",G12<>0),J12/G12,"") | L12: Photo Print: Photo Print 47 | M12: https://cdn.shopify.com/s/files/1/0936/8656/3183/files/PXL_20250819_194112806.jpg?v=1761563377
A13: BRAC_PP48 | B13: bracelet | C13: Bracelet - Photo Print 48 | D13: Photo Print ID: Photo Print 48 | J13: =IF(AND(G13<>"",I13<>""),G13-I13,"") | K13: =IF(AND(G13<>"",G13<>0),J13/G13,"") | L13: Photo Print: Photo Print 48 | M13: https://cdn.shopify.com/s/files/1/0936/8656/3183/files/PXL_20250819_175142414.jpg?v=1761563377
A14: BRAC_PP49 | B14: bracelet | C14: Bracelet - Photo Print 49 | D14: Photo Print ID: Photo Print 49 | J14: =IF(AND(G14<>"",I14<>""),G14-I14,"") | K14: =IF(AND(G14<>"",G14<>0),J14/G14,"") | L14: Photo Print: Photo Print 49 | M14: https://cdn.shopify.com/s/files/1/0936/8656/3183/files/PXL_20250819_175715094.jpg?v=1761563377
... A51: BRAC_PP9 | B51: bracelet | C51: Bracelet - Photo Print 9 | D51: Photo Print ID: Photo Print 9 | J51: =IF(AND(G51<>"",I51<>""),G51-I51,"") | K51: =IF(AND(G51<>"",G51<>0),J51/G51,"") | L51: Photo Print: Photo Print 9 | M51: https://cdn.shopify.com/s/files/1/0936/8656/3183/files/PXL_20250819_173937234.jpg?v=1761563364
A52: PIID000016 | B52: bracelet | C52: 4mm MoissaniteTennis Bracelet | D52: 925 18 CTW 4mm moissanite tennis bracelet | E52: 925 Sterling Silver | F52: size 8 | I52: 25 | J52: =IF(AND(G52<>"",I52<>""),G52-I52,"") | K52: =IF(AND(G52<>"",G52<>0),J52/G52,"")
A53: PIID000017 | B53: bracelet | C53: 3 stone saphire gold bracelet | D53: 3 saphire stone 14k hinge bracelet | F53: size 8 | I53: 0 | J53: =IF(AND(G53<>"",I53<>""),G53-I53,"") | K53: =IF(AND(G53<>"",G53<>0),J53/G53,"")
A54: PIID000018 | B54: bracelet | C54: Cubic Zirconia tennis bracelet | D54: 24 CTW cubic zirconia tennis bracelet | F54: size 7 | I54: 0 | J54: =IF(AND(G54<>"",I54<>""),G54-I54,"") | K54: =IF(AND(G54<>"",G54<>0),J54/G54,"")
A55: PIID000019 | B55: bracelet | C55: 14 k gold bracelet | D55: 14 k gold bracelet size 7 | E55: Gold | F55: size 7 | I55: 0 | J55: =IF(AND(G55<>"",I55<>""),G55-I55,"") | K55: =IF(AND(G55<>"",G55<>0),J55/G55,"")
A56: PIID000020 | B56: bracelet | C56: 12k plated 925 7 stone bracelet | D56: 12k over 925. 7 glass faux diamond bracelet | E56: 925 Sterling Silver | F56: size 7.5 | J56: =IF(AND(G56<>"",I56<>""),G56-I56,"") | K56: =IF(AND(G56<>"",G56<>0),J56/G56,"")
A57: PIID000022 | B57: bracelet | C57: 2 tone diamond cut 925 | D57: 925 diamond cut 2 tone twist chain | E57: 925 Sterling Silver | F57: size 7 | I57: 25 | J57: =IF(AND(G57<>"",I57<>""),G57-I57,"") | K57: =IF(AND(G57<>"",G57<>0),J57/G57,"")
A58: EAR_MOISS_DROP | B58: earring | C58: Moissanite Drop Earrings | D58: Photo Print ID: Moissanite drop earrings | J58: =IF(AND(G58<>"",I58<>""),G58-I58,"") | K58: =IF(AND(G58<>"",G58<>0),J58/G58,"") | L58: Photo Print: Moissanite drop earrings | M58: https://cdn.shopify.com/s/files/1/0936/8656/3183/files/PC000023.jpg?v=1764408730
A59: EAR_PP257 | B59: earring | C59: Earrings - Photo Print 257 | D59: Photo Print ID: Photo Print 257 | J59: =IF(AND(G59<>"",I59<>""),G59-I59,"") | K59: =IF(AND(G59<>"",G59<>0),J59/G59,"") | L59: Photo Print: Photo Print 257 | M59: https://cdn.shopify.com/s/files/1/0936/8656/3183/files/PXL_20251108_040536996.jpg?v=1762842149
A60: EAR_PP259 | B60: earring | C60: Earrings - Photo Print 259 | D60: Photo Print ID: Photo Print 259 | J60: =IF(AND(G60<>"",I60<>""),G60-I60,"") | K60: =IF(AND(G60<>"",G60<>0),J60/G60,"") | L60: Photo Print: Photo Print 259 | M60: https://cdn.shopify.com/s/files/1/0936/8656/3183/files/PXL_20251108_040704002.jpg?v=1762842149
A61: EAR_PP261 | B61: earring | C61: Earrings - Photo Print 261 | D61: Photo Print ID: Photo Print 261 | J61: =IF(AND(G61<>"",I61<>""),G61-I61,"") | K61: =IF(AND(G61<>"",G61<>0),J61/G61,"") | L61: Photo Print: Photo Print 261 | M61: https://cdn.shopify.com/s/files/1/0936/8656/3183/files/PXL_20251108_040710433.jpg?v=1762842150
A62: EAR_PP263 | B62: earring | C62: Earrings - Photo Print 263 | D62: Photo Print ID: Photo Print 263 | J62: =IF(AND(G62<>"",I62<>""),G62-I62,"") | K62: =IF(AND(G62<>"",G62<>0),J62/G62,"") | L62: Photo Print: Photo Print 263 | M62: https://cdn.shopify.com/s/files/1/0936/8656/3183/files/PXL_20251108_040139833.jpg?v=1762842150
A63: EAR_PP280 | B63: earring | C63: Earrings - Photo Print 280 | D63: Photo Print ID: Photo Print 280 | J63: =IF(AND(G63<>"",I63<>""),G63-I63,"") | K63: =IF(AND(G63<>"",G63<>0),J63/G63,"") | L63: Photo Print: Photo Print 280 | M63: https://cdn.shopify.com/s/files/1/0936/8656/3183/files/PXL_20251108_040710433_b5b22ba0-df8f-4c1c-9420-452483e97f22.jpg?v=1762842153
A64: EAR_PP287 | B64: earring | C64: Earrings - Photo Print 287 | D64: Photo Print ID: Photo Print 287 | J64: =IF(AND(G64<>"",I64<>""),G64-I64,"") | K64: =IF(AND(G64<>"",G64<>0),J64/G64,"") | L64: Photo Print: Photo Print 287 | M64: https://cdn.shopify.com/s/files/1/0936/8656/3183/files/PXL_20251108_040221416.jpg?v=1762842153
A65: EAR_PP291 | B65: earring | C65: Earrings - Photo Print 291 | D65: Photo Print ID: Photo Print 291 | J65: =IF(AND(G65<>"",I65<>""),G65-I65,"") | K65: =IF(AND(G65<>"",G65<>0),J65/G65,"") | L65: Photo Print: Photo Print 291 | M65: https://cdn.shopify.com/s/files/1/0936/8656/3183/files/PXL_20251108_040536996_848b69f9-9d7a-4128-9910-4b318ec32693.jpg?v=1762842153
A66: EAR_PP292 | B66: earring | C66: Earrings - Photo Print 292 | D66: Photo Print ID: Photo Print 292 | J66: =IF(AND(G66<>"",I66<>""),G66-I66,"") | K66: =IF(AND(G66<>"",G66<>0),J66/G66,"") | L66: Photo Print: Photo Print 292 | M66: https://cdn.shopify.com/s/files/1/0936/8656/3183/files/PXL_20251108_040704002_5f2fa9e7-f049-4444-96fe-962507ec58bc.jpg?v=1762842153
A67: EAR_PP297 | B67: earring | C67: Earrings - Photo Print 297 | D67: Photo Print ID: Photo Print 297 | J67: =IF(AND(G67<>"",I67<>""),G67-I67,"") | K67: =IF(AND(G67<>"",G67<>0),J67/G67,"") | L67: Photo Print: Photo Print 297 | M67: https://cdn.shopify.com/s/files/1/0936/8656/3183/files/PXL_20251108_042407875.jpg?v=1762842154
A68: EAR_PP299 | B68: earring | C68: Earrings - Photo Print 299 | D68: Photo Print ID: Photo Print 299 | J68: =IF(AND(G68<>"",I68<>""),G68-I68,"") | K68: =IF(AND(G68<>"",G68<>0),J68/G68,"") | L68: Photo Print: Photo Print 299 | M68: https://cdn.shopify.com/s/files/1/0936/8656/3183/files/PXL_20251108_040221416_23019738-cc17-4575-991a-fc5e788baf0d.jpg?v=1762842155
A69: EAR_PP300 | B69: earring | C69: Earrings - Photo Print 300 | D69: Photo Print ID: Photo Print 300 | J69: =IF(AND(G69<>"",I69<>""),G69-I69,"") | K69: =IF(AND(G69<>"",G69<>0),J69/G69,"") | L69: Photo Print: Photo Print 300 | M69: https://cdn.shopify.com/s/files/1/0936/8656/3183/files/PXL_20251108_040139833_e6e05fb8-d499-43ef-a509-fd46954be110.jpg?v=1762842155
... A87: EAR_PP396 | B87: earring | C87: Earrings - Photo Print 396 | D87: Photo Print ID: Photo Print 396 | J87: =IF(AND(G87<>"",I87<>""),G87-I87,"") | K87: =IF(AND(G87<>"",G87<>0),J87/G87,"") | L87: Photo Print: Photo Print 396 | M87: https://cdn.shopify.com/s/files/1/0936/8656/3183/files/PC000021.jpg?v=1764408401
A88: PIID000013 | B88: earring | C88: .5 CTW | D88: 925 .5CTW stud earrings | E88: 925 Sterling Silver | F88: na | I88: 0 | J88: =IF(AND(G88<>"",I88<>""),G88-I88,"") | K88: =IF(AND(G88<>"",G88<>0),J88/G88,"")
A89: PIID000014 | B89: earring | C89: 2 CTW | D89: Stainless Steal 2 CTW cubic zirconia stud | F89: na | I89: 0 | J89: =IF(AND(G89<>"",I89<>""),G89-I89,"") | K89: =IF(AND(G89<>"",G89<>0),J89/G89,"")
A90: PIID000015 | B90: earring | C90: 1.5 CTW Moissanite | D90: 14k white gold over 925 1.5 CTW moissanite flower stud | E90: 925 Sterling Silver | F90: na | I90: 25 | J90: =IF(AND(G90<>"",I90<>""),G90-I90,"") | K90: =IF(AND(G90<>"",G90<>0),J90/G90,"")
A91: PIID000023 | B91: earring | C91: 1/4 CTW Diamond Stud | D91: 1/4 CTW 14k white gold Diamond Stud | E91: Gold | F91: na | H91: 125 | I91: 0 | J91: =IF(AND(G91<>"",I91<>""),G91-I91,"") | K91: =IF(AND(G91<>"",G91<>0),J91/G91,"")
A92: PIID000024 | B92: earring | C92: 1/2 CTW Diamond Stud | D92: 1/2 CTW 14k White gold Diamond Stud | E92: Gold | F92: na | H92: 350 | I92: 0 | J92: =IF(AND(G92<>"",I92<>""),G92-I92,"") | K92: =IF(AND(G92<>"",G92<>0),J92/G92,"")
A93: PIID000025 | B93: earring | C93: Baguette solitaire emerald and natural diamond hoop earringws 14k yellow gold | D93: 14k yellow gold natural diamond hoop emerald drop | E93: Gold | F93: na | H93: 780 | I93: 25 | J93: =IF(AND(G93<>"",I93<>""),G93-I93,"") | K93: =IF(AND(G93<>"",G93<>0),J93/G93,"")
...

Sheet Raw Materials
A1: Material ID | B1: Material Type | C1: Description | D1: Unit | E1: Quantity in Stock | F1: Cost per Unit | G1: Total Value | H1: Reorder Point | I1: Supplier | J1: Notes
A2: CHAIN_001 | B2: Chain | C2: 18" Gold Plated Chain | D2: inches | E2: 240 | F2: 0.5 | G2: =IF(AND(E2<>"",F2<>""),E2*F2,"")
A3: CHAIN_002 | B3: Chain | C3: 20" Sterling Silver Chain | D3: inches | E3: 180 | F3: 0.75 | G3: =IF(AND(E3<>"",F3<>""),E3*F3,"")
A4: GEM_001 | B4: Gemstone | C4: 4mm Moissanite | D4: pieces | E4: 50 | F4: 2 | G4: =IF(AND(E4<>"",F4<>""),E4*F4,"") | H4: 20
A5: GEM_002 | B5: Gemstone | C5: Cubic Zirconia 6mm | D5: pieces | E5: 75 | F5: 1.5 | G5: =IF(AND(E5<>"",F5<>""),E5*F5,"") | H5: 25
A6: WIRE_001 | B6: Wire | C6: 20g Silver Wire | D6: feet | E6: 100 | F6: 0.25 | G6: =IF(AND(E6<>"",F6<>""),E6*F6,"") | H6: 50

Sheet Image Management
A1: IMAGE MANAGEMENT & URL GENERATOR
A3: HOW TO ADD IMAGES TO YOUR INVENTORY
A4: OPTION 1: Upload to Shopify (or your website)
A5: 1. | B5: Upload your jewelry photo to Shopify
A6: 2. | B6: Copy the image URL (right-click image > Copy image address)
A7: 3. | B7: Paste the URL in the "Images" column in Finished Inventory
A9: OPTION 2: Upload to Google Drive (FREE)
A10: 1. | B10: Upload photo to Google Drive
A11: 2. | B11: Right-click > Share > Change to "Anyone with link"
A12: 3. | B12: Copy the shareable link
A13: 4. | B13: Convert the link using the tool below
A15: OPTION 3: Use Imgur (FREE)
A16: 1. | B16: Go to imgur.com
A17: 2. | B17: Click "New post" and upload your image
A18: 3. | B18: Right-click the image > Copy image address
A19: 4. | B19: Paste in the "Images" column
A22: GOOGLE DRIVE URL CONVERTER
A23: Paste Google Drive Share Link:
A24: Direct Image URL: | B24: =IF(B23="","",IF(ISNUMBER(SEARCH("drive.google.com",B23)),"https://drive.google.com/uc?export=view&id=" & MID(B23,FIND("/d/",B23)+3,FIND("/view",B23)-FIND("/d/",B23)-3),"Invalid Google Drive link"))
A25: Copy the Direct Image URL above and paste it into your Finished Inventory "Images" column
A28: AUTO URL GENERATOR (For Bulk Upload)
A29: Your Base URL Pattern: | B29: https://cdn.shopify.com/s/files/1/0936/8656/3183/files/
A30: Instructions: | B30: 1. Update the base URL above if needed 2. Use the table below to generate URLs
A32: SKU | B32: Filename | C32: Generated URL | D32: Copy to Finished Inventory
C33: =IF(B33="","",$B$29&B33) | D33: ← Copy this URL to Finished Inventory
C34: =IF(B34="","",$B$29&B34) | D34: ← Copy this URL to Finished Inventory
C35: =IF(B35="","",$B$29&B35) | D35: ← Copy this URL to Finished Inventory
C36: =IF(B36="","",$B$29&B36) | D36: ← Copy this URL to Finished Inventory
C37: =IF(B37="","",$B$29&B37) | D37: ← Copy this URL to Finished Inventory
C38: =IF(B38="","",$B$29&B38) | D38: ← Copy this URL to Finished Inventory
C39: =IF(B39="","",$B$29&B39) | D39: ← Copy this URL to Finished Inventory
C40: =IF(B40="","",$B$29&B40) | D40: ← Copy this URL to Finished Inventory
C41: =IF(B41="","",$B$29&B41) | D41: ← Copy this URL to Finished Inventory
C42: =IF(B42="","",$B$29&B42) | D42: ← Copy this URL to Finished Inventory
C43: =IF(B43="","",$B$29&B43) | D43: ← Copy this URL to Finished Inventory
C44: =IF(B44="","",$B$29&B44) | D44: ← Copy this URL to Finished Inventory
... C52: =IF(B52="","",$B$29&B52) | D52: ← Copy this URL to Finished Inventory

Sheet Spool Tracker
A1: Spool ID | B1: Material Type | C1: Description | D1: Original Length | E1: Current Length | F1: Used | G1: Unit | H1: Cost per Unit | I1: Remaining Value | J1: Date Added | K1: Notes
A2: SPOOL_001 | B2: Chain | C2: 18" Gold Chain Spool | D2: 500 | E2: 240 | F2: =IF(AND(D2<>"",E2<>""),D2-E2,"") | G2: inches | H2: 0.5 | I2: =IF(AND(E2<>"",H2<>""),E2*H2,"") | J2: 2025-01-01 | K2: Main supplier spool
A3: SPOOL_002 | B3: Chain | C3: 20" Silver Chain Spool | D3: 400 | E3: 180 | F3: =IF(AND(D3<>"",E3<>""),D3-E3,"") | G3: inches | H3: 0.75 | I3: =IF(AND(E3<>"",H3<>""),E3*H3,"") | J3: 2025-01-01
A4: SPOOL_003 | B4: Wire | C4: 20g Silver Wire Spool | D4: 200 | E4: 100 | F4: =IF(AND(D4<>"",E4<>""),D4-E4,"") | G4: feet | H4: 0.25 | I4: =IF(AND(E4<>"",H4<>""),E4*H4,"") | J4: 2025-01-01

Sheet Usage Log
A1: Date | B1: Spool ID | C1: Material Used | D1: Amount Used | E1: Unit | F1: Used For (SKU) | G1: Notes
A2: INSTRUCTIONS: When you cut from a spool, log it here. Then manually update the "Current Length" in the Spool Tracker sheet.

Sheet Bundle Builder
A1: CUSTOM BUNDLE BUILDER
A2: Enter SKUs below to build a custom bundle. Prices will auto-calculate.
A3: Bundle Name: | C3: Target Price: | E3: Bundle Discount %:
A5: # | B5: SKU | C5: Item Name | D5: Category | E5: Price | F5: Include? | G5: Line Total
A6: 1 | C6: =IFERROR(VLOOKUP(B6,'Finished Inventory'!A:C,3,FALSE()),"") | D6: =IFERROR(VLOOKUP(B6,'Finished Inventory'!A:B,2,FALSE()),"") | E6: =IFERROR(VLOOKUP(B6,'Finished Inventory'!A:G,7,FALSE()),"") | F6: Yes | G6: =IF(F6="Yes",E6,0)
A7: 2 | C7: =IFERROR(VLOOKUP(B7,'Finished Inventory'!A:C,3,FALSE()),"") | D7: =IFERROR(VLOOKUP(B7,'Finished Inventory'!A:B,2,FALSE()),"") | E7: =IFERROR(VLOOKUP(B7,'Finished Inventory'!A:G,7,FALSE()),"") | F7: Yes | G7: =IF(F7="Yes",E7,0)
A8: 3 | C8: =IFERROR(VLOOKUP(B8,'Finished Inventory'!A:C,3,FALSE()),"") | D8: =IFERROR(VLOOKUP(B8,'Finished Inventory'!A:B,2,FALSE()),"") | E8: =IFERROR(VLOOKUP(B8,'Finished Inventory'!A:G,7,FALSE()),"") | F8: Yes | G8: =IF(F8="Yes",E8,0)
A9: 4 | C9: =IFERROR(VLOOKUP(B9,'Finished Inventory'!A:C,3,FALSE()),"") | D9: =IFERROR(VLOOKUP(B9,'Finished Inventory'!A:B,2,FALSE()),"") | E9: =IFERROR(VLOOKUP(B9,'Finished Inventory'!A:G,7,FALSE()),"") | F9: Yes | G9: =IF(F9="Yes",E9,0)
A10: 5 | C10: =IFERROR(VLOOKUP(B10,'Finished Inventory'!A:C,3,FALSE()),"") | D10: =IFERROR(VLOOKUP(B10,'Finished Inventory'!A:B,2,FALSE()),"") | E10: =IFERROR(VLOOKUP(B10,'Finished Inventory'!A:G,7,FALSE()),"") | F10: Yes | G10: =IF(F10="Yes",E10,0)
A11: 6 | C11: =IFERROR(VLOOKUP(B11,'Finished Inventory'!A:C,3,FALSE()),"") | D11: =IFERROR(VLOOKUP(B11,'Finished Inventory'!A:B,2,FALSE()),"") | E11: =IFERROR(VLOOKUP(B11,'Finished Inventory'!A:G,7,FALSE()),"") | F11: Yes | G11: =IF(F11="Yes",E11,0)
A12: 7 | C12: =IFERROR(VLOOKUP(B12,'Finished Inventory'!A:C,3,FALSE()),"") | D12: =IFERROR(VLOOKUP(B12,'Finished Inventory'!A:B,2,FALSE()),"") | E12: =IFERROR(VLOOKUP(B12,'Finished Inventory'!A:G,7,FALSE()),"") | F12: Yes | G12: =IF(F12="Yes",E12,0)
A13: 8 | C13: =IFERROR(VLOOKUP(B13,'Finished Inventory'!A:C,3,FALSE()),"") | D13: =IFERROR(VLOOKUP(B13,'Finished Inventory'!A:B,2,FALSE()),"") | E13: =IFERROR(VLOOKUP(B13,'Finished Inventory'!A:G,7,FALSE()),"") | F13: Yes | G13: =IF(F13="Yes",E13,0)
A14: 9 | C14: =IFERROR(VLOOKUP(B14,'Finished Inventory'!A:C,3,FALSE()),"") | D14: =IFERROR(VLOOKUP(B14,'Finished Inventory'!A:B,2,FALSE()),"") | E14: =IFERROR(VLOOKUP(B14,'Finished Inventory'!A:G,7,FALSE()),"") | F14: Yes | G14: =IF(F14="Yes",E14,0)
A15: 10 | C15: =IFERROR(VLOOKUP(B15,'Finished Inventory'!A:C,3,FALSE()),"") | D15: =IFERROR(VLOOKUP(B15,'Finished Inventory'!A:B,2,FALSE()),"") | E15: =IFERROR(VLOOKUP(B15,'Finished Inventory'!A:G,7,FALSE()),"") | F15: Yes | G15: =IF(F15="Yes",E15,0)
A16: 11 | C16: =IFERROR(VLOOKUP(B16,'Finished Inventory'!A:C,3,FALSE()),"") | D16: =IFERROR(VLOOKUP(B16,'Finished Inventory'!A:B,2,FALSE()),"") | E16: =IFERROR(VLOOKUP(B16,'Finished Inventory'!A:G,7,FALSE()),"") | F16: Yes | G16: =IF(F16="Yes",E16,0)
A17: 12 | C17: =IFERROR(VLOOKUP(B17,'Finished Inventory'!A:C,3,FALSE()),"") | D17: =IFERROR(VLOOKUP(B17,'Finished Inventory'!A:B,2,FALSE()),"") | E17: =IFERROR(VLOOKUP(B17,'Finished Inventory'!A:G,7,FALSE()),"") | F17: Yes | G17: =IF(F17="Yes",E17,0)
... A25: 20 | C25: =IFERROR(VLOOKUP(B25,'Finished Inventory'!A:C,3,FALSE()),"") | D25: =IFERROR(VLOOKUP(B25,'Finished Inventory'!A:B,2,FALSE()),"") | E25: =IFERROR(VLOOKUP(B25,'Finished Inventory'!A:G,7,FALSE()),"") | F25: Yes | G25: =IF(F25="Yes",E25,0)
E27: Subtotal: | G27: =SUM(G6:G25)
E28: Discount: | G28: =G27*F3
E29: Bundle Total: | G29: =G27-G28

Sheet Search & Filter
A1: SEARCH & FILTER
A3: Filter Criteria:
A4: Category:
A5: Metal Type:
A6: Price Range Min:
A7: Price Range Max:
A8: Search Text:
A10: TIP: Use Excel's built-in Filter (Data > Filter) on the Finished Inventory sheet for advanced filtering.
A12: QUICK STATS
A13: Total Items: | B13: =COUNTA('Finished Inventory'!A:A)-1
A14: Total Inventory Value: | B14: =SUMIF('Finished Inventory'!G:G,">0",'Finished Inventory'!G:G)
A15: Average Price: | B15: =AVERAGEIF('Finished Inventory'!G:G,">0",'Finished Inventory'!G:G)
A17: Items by Category:
A18: Necklace: | B18: =COUNTIF('Finished Inventory'!B:B,"necklace")
A19: Bracelet: | B19: =COUNTIF('Finished Inventory'!B:B,"bracelet")
A20: Earring: | B20: =COUNTIF('Finished Inventory'!B:B,"earring")
A21: Ring: | B21: =COUNTIF('Finished Inventory'!B:B,"ring")
A22: Set: | B22: =COUNTIF('Finished Inventory'!B:B,"set")

Sheet Image Upload Guide
A1: 📸 QUICK IMAGE UPLOAD GUIDE
A3: EASIEST METHOD: Google Drive (100% FREE)
A5: 1. Create a folder in Google Drive for jewelry images
A6: 2. Upload all your jewelry photos to that folder
A7: 3. For each photo:
A8: • Right-click the image > Share
A9: • Change to "Anyone with the link"
A10: • Click "Copy link"
A11: • Go to "Image Management" sheet
A12: • Paste in the Google Drive URL Converter
A13: • Copy the generated Direct Image URL
A14: • Paste in your Finished Inventory "Images" column
... A40: ✓ Dropbox (2GB free)
